Workbook
Name NomorTO: '[1]TO HEADER'!$A:$A

Sheet TEMPLATE HITUNG VOLUME
B2: 10 PO NHD RSUD TUANKU IMAM BONJOL - 324BMHP-BLUDVIII2026 | L2: JUMLAH LOAD KIRIMAN VS COST RATIO BIAYA KIRIM
B4: NO | C4: NO ITEM | D4: ITEM DESCRIPTION | E4: QTY | F4: UoM | G4: BERAT (KG) | H4: VOLUMETRIC (KG) | I4: Berat Volumetrik Darat/laut (KG) | J4: Berat Volumetrik Udara (KG) | K4: Kubikasi M3 | L4: Koli | N4: Stock Cabang | P4: Update Stock Tanggal :
B5: TOTAL | E5: =SUM(E7:E16) -> 18700 | F5: =SUM(F7:F16) -> 0 | G5: =SUM(G7:G16) -> 141.9075 | H5: =SUM(H7:H16) -> 255.76858 | I5: =SUM(I7:I7) -> 14.345068 | J5: =SUM(J7:J7) -> 9.5633789 | K5: =SUM(K7:K7) -> 0.12241125 | L5: =SUM(L7:L16) -> 16 | P5: =[2]Sheet1!$A$1 -> 46175
B7: 1 | C7: DS01T2613R-N | D7: =VLOOKUP(C7,'MASTER VOLUME'!$B$3:$C$487,2,0) -> DISP.SYRINGE 1ML TB 26GX1/2"/2613 LUER SLIP R-N | E7: 1500 | F7: =UPPER(VLOOKUP(C7,'MASTER VOLUME'!$B$3:$AR$549,23,0)) -> PCS | G7: =(VLOOKUP(C7,'MASTER VOLUME'!$B$1:$AD$487,17,0)/VLOOKUP(C7,'MASTER VOLUME'!$B$1:$AD$487,12,0))*E7 -> 8.09625 | H7: =(VLOOKUP(C7,'MASTER VOLUME'!$B$3:$S$487,6,0)*VLOOKUP(C7,'MASTER VOLUME'!$B$3:$S$487,7,0)*VLOOKUP(C7,'MASTER VOLUME'!$B$3:$S$487,8,0)/4000)*(E7/VLOOKUP(C7,'MASTER VOLUME'!$B$3:$S$487,12,0)) -> 14.345068 | I7: =(VLOOKUP(C7,'MASTER VOLUME'!$B$3:$U$487,6,0)*VLOOKUP(C7,'MASTER VOLUME'!$B$3:$U$487,7,0)*VLOOKUP(C7,'MASTER VOLUME'!$B$3:$U$487,8,0)/4000)*(E7/VLOOKUP(C7,'MASTER VOLUME'!$B$3:$U$487,12,0)) -> 14.345068 | J7: =(VLOOKUP(C7,'MASTER VOLUME'!$B$3:$U$487,6,0)*VLOOKUP(C7,'MASTER VOLUME'!$B$3:$U$487,7,0)*VLOOKUP(C7,'MASTER VOLUME'!$B$3:$U$487,8,0)/6000)*(E7/VLOOKUP(C7,'MASTER VOLUME'!$B$3:$U$487,12,0)) -> 9.5633789 | K7: =VLOOKUP(C7,'MASTER VOLUME'!$B$3:$U$487,9,0)*L7 -> 0.12241125 | L7: =ROUNDUP(E7/VLOOKUP(C7,'MASTER VOLUME'!$B$3:$U$487,12,0),0) -> 1 | N7: =VLOOKUP(C7,[2]Sheet1!$A$5:$C$87,3,0) -> 72125
B8: 2 | C8: DS10L2138R-N | D8: =VLOOKUP(C8,'MASTER VOLUME'!$B$3:$C$487,2,0) -> DISP.SYRINGE 10ML LUER LOCK with NEEDLE 21Gx1 1/2" | E8: 4000 | F8: =UPPER(VLOOKUP(C8,'MASTER VOLUME'!$B$3:$AR$549,23,0)) -> PCS | G8: =(VLOOKUP(C8,'MASTER VOLUME'!$B$1:$AD$487,17,0)/VLOOKUP(C8,'MASTER VOLUME'!$B$1:$AD$487,12,0))*E8 -> 57.88 | H8: =(VLOOKUP(C8,'MASTER VOLUME'!$B$3:$S$487,6,0)*VLOOKUP(C8,'MASTER VOLUME'!$B$3:$S$487,7,0)*VLOOKUP(C8,'MASTER VOLUME'!$B$3:$S$487,8,0)/4000)*(E8/VLOOKUP(C8,'MASTER VOLUME'!$B$3:$S$487,12,0)) -> 101.2095 | I8: =(VLOOKUP(C8,'MASTER VOLUME'!$B$3:$U$487,6,0)*VLOOKUP(C8,'MASTER VOLUME'!$B$3:$U$487,7,0)*VLOOKUP(C8,'MASTER VOLUME'!$B$3:$U$487,8,0)/4000)*(E8/VLOOKUP(C8,'MASTER VOLUME'!$B$3:$U$487,12,0)) -> 101.2095 | J8: =(VLOOKUP(C8,'MASTER VOLUME'!$B$3:$U$487,6,0)*VLOOKUP(C8,'MASTER VOLUME'!$B$3:$U$487,7,0)*VLOOKUP(C8,'MASTER VOLUME'!$B$3:$U$487,8,0)/6000)*(E8/VLOOKUP(C8,'MASTER VOLUME'!$B$3:$U$487,12,0)) -> 67.473 | K8: =VLOOKUP(C8,'MASTER VOLUME'!$B$3:$U$487,9,0)*L8 -> 0.404838 | L8: =ROUNDUP(E8/VLOOKUP(C8,'MASTER VOLUME'!$B$3:$U$487,12,0),0) -> 4 | N8: =VLOOKUP(C8,[2]Sheet1!$A$5:$C$87,3,0) -> 767966
B9: 3 | C9: DS20LSR-N | D9: =VLOOKUP(C9,'MASTER VOLUME'!$B$3:$C$487,2,0) -> DISP.SYRINGE 20ML without NEEDLE LUER SLIP R-N | E9: 100 | F9: =UPPER(VLOOKUP(C9,'MASTER VOLUME'!$B$3:$AR$549,23,0)) -> PCS | G9: =(VLOOKUP(C9,'MASTER VOLUME'!$B$1:$AD$487,17,0)/VLOOKUP(C9,'MASTER VOLUME'!$B$1:$AD$487,12,0))*E9 -> 1.95125 | H9: =(VLOOKUP(C9,'MASTER VOLUME'!$B$3:$S$487,6,0)*VLOOKUP(C9,'MASTER VOLUME'!$B$3:$S$487,7,0)*VLOOKUP(C9,'MASTER VOLUME'!$B$3:$S$487,8,0)/4000)*(E9/VLOOKUP(C9,'MASTER VOLUME'!$B$3:$S$487,12,0)) -> 3.8070703 | I9: =(VLOOKUP(C9,'MASTER VOLUME'!$B$3:$U$487,6,0)*VLOOKUP(C9,'MASTER VOLUME'!$B$3:$U$487,7,0)*VLOOKUP(C9,'MASTER VOLUME'!$B$3:$U$487,8,0)/4000)*(E9/VLOOKUP(C9,'MASTER VOLUME'!$B$3:$U$487,12,0)) -> 3.8070703 | J9: =(VLOOKUP(C9,'MASTER VOLUME'!$B$3:$U$487,6,0)*VLOOKUP(C9,'MASTER VOLUME'!$B$3:$U$487,7,0)*VLOOKUP(C9,'MASTER VOLUME'!$B$3:$U$487,8,0)/6000)*(E9/VLOOKUP(C9,'MASTER VOLUME'!$B$3:$U$487,12,0)) -> 2.5380469 | K9: =VLOOKUP(C9,'MASTER VOLUME'!$B$3:$U$487,9,0)*L9 -> 0.12182625 | L9: =ROUNDUP(E9/VLOOKUP(C9,'MASTER VOLUME'!$B$3:$U$487,12,0),0) -> 1 | N9: =VLOOKUP(C9,[2]Sheet1!$A$5:$C$87,3,0) -> 44371
B10: 4 | C10: DS03L2332R-N | D10: =VLOOKUP(C10,'MASTER VOLUME'!$B$3:$C$487,2,0) -> DISP.SYRINGE 3ML LUER LOCK with NEEDLE 23GX1 1/4" | E10: 8000 | F10: =UPPER(VLOOKUP(C10,'MASTER VOLUME'!$B$3:$AR$549,23,0)) -> PCS | G10: =(VLOOKUP(C10,'MASTER VOLUME'!$B$1:$AD$487,17,0)/VLOOKUP(C10,'MASTER VOLUME'!$B$1:$AD$487,12,0))*E10 -> 54.273333 | H10: =(VLOOKUP(C10,'MASTER VOLUME'!$B$3:$S$487,6,0)*VLOOKUP(C10,'MASTER VOLUME'!$B$3:$S$487,7,0)*VLOOKUP(C10,'MASTER VOLUME'!$B$3:$S$487,8,0)/4000)*(E10/VLOOKUP(C10,'MASTER VOLUME'!$B$3:$S$487,12,0)) -> 100.92469 | I10: =(VLOOKUP(C10,'MASTER VOLUME'!$B$3:$U$487,6,0)*VLOOKUP(C10,'MASTER VOLUME'!$B$3:$U$487,7,0)*VLOOKUP(C10,'MASTER VOLUME'!$B$3:$U$487,8,0)/4000)*(E10/VLOOKUP(C10,'MASTER VOLUME'!$B$3:$U$487,12,0)) -> 100.92469 | J10: =(VLOOKUP(C10,'MASTER VOLUME'!$B$3:$U$487,6,0)*VLOOKUP(C10,'MASTER VOLUME'!$B$3:$U$487,7,0)*VLOOKUP(C10,'MASTER VOLUME'!$B$3:$U$487,8,0)/6000)*(E10/VLOOKUP(C10,'MASTER VOLUME'!$B$3:$U$487,12,0)) -> 67.283125 | K10: =VLOOKUP(C10,'MASTER VOLUME'!$B$3:$U$487,9,0)*L10 -> 0.4844385 | L10: =ROUNDUP(E10/VLOOKUP(C10,'MASTER VOLUME'!$B$3:$U$487,12,0),0) -> 4 | N10: =VLOOKUP(C10,[2]Sheet1!$A$5:$C$87,3,0) -> 1430086
B11: 5 | C11: 7022V PDM-13-BLUE | D11: =VLOOKUP(C11,'MASTER VOLUME'!$B$3:$C$487,2,0) -> Thermal Wristband 7022V-13-PDM BLUE | E11: 1000 | F11: =UPPER(VLOOKUP(C11,'MASTER VOLUME'!$B$3:$AR$549,23,0)) -> PCS | G11: =(VLOOKUP(C11,'MASTER VOLUME'!$B$1:$AD$487,17,0)/VLOOKUP(C11,'MASTER VOLUME'!$B$1:$AD$487,12,0))*E11 -> 1.1733333 | H11: =(VLOOKUP(C11,'MASTER VOLUME'!$B$3:$S$487,6,0)*VLOOKUP(C11,'MASTER VOLUME'!$B$3:$S$487,7,0)*VLOOKUP(C11,'MASTER VOLUME'!$B$3:$S$487,8,0)/4000)*(E11/VLOOKUP(C11,'MASTER VOLUME'!$B$3:$S$487,12,0)) -> 0.943 | I11: =(VLOOKUP(C11,'MASTER VOLUME'!$B$3:$U$487,6,0)*VLOOKUP(C11,'MASTER VOLUME'!$B$3:$U$487,7,0)*VLOOKUP(C11,'MASTER VOLUME'!$B$3:$U$487,8,0)/4000)*(E11/VLOOKUP(C11,'MASTER VOLUME'!$B$3:$U$487,12,0)) -> 0.943 | J11: =(VLOOKUP(C11,'MASTER VOLUME'!$B$3:$U$487,6,0)*VLOOKUP(C11,'MASTER VOLUME'!$B$3:$U$487,7,0)*VLOOKUP(C11,'MASTER VOLUME'!$B$3:$U$487,8,0)/6000)*(E11/VLOOKUP(C11,'MASTER VOLUME'!$B$3:$U$487,12,0)) -> 0.62866667 | K11: =VLOOKUP(C11,'MASTER VOLUME'!$B$3:$U$487,9,0)*L11 -> 0.05658 | L11: =ROUNDUP(E11/VLOOKUP(C11,'MASTER VOLUME'!$B$3:$U$487,12,0),0) -> 1 | N11: =VLOOKUP(C11,[2]Sheet1!$A$5:$C$87,3,0) -> 21000
B12: 6 | C12: 7022v PDM-12-PINK | D12: =VLOOKUP(C12,'MASTER VOLUME'!$B$3:$C$487,2,0) -> Thermal Wristband 7022V-12-PDM PINK | E12: 1000 | F12: =UPPER(VLOOKUP(C12,'MASTER VOLUME'!$B$3:$AR$549,23,0)) -> PCS | G12: =(VLOOKUP(C12,'MASTER VOLUME'!$B$1:$AD$487,17,0)/VLOOKUP(C12,'MASTER VOLUME'!$B$1:$AD$487,12,0))*E12 -> 1.1733333 | H12: =(VLOOKUP(C12,'MASTER VOLUME'!$B$3:$S$487,6,0)*VLOOKUP(C12,'MASTER VOLUME'!$B$3:$S$487,7,0)*VLOOKUP(C12,'MASTER VOLUME'!$B$3:$S$487,8,0)/4000)*(E12/VLOOKUP(C12,'MASTER VOLUME'!$B$3:$S$487,12,0)) -> 0.943 | I12: =(VLOOKUP(C12,'MASTER VOLUME'!$B$3:$U$487,6,0)*VLOOKUP(C12,'MASTER VOLUME'!$B$3:$U$487,7,0)*VLOOKUP(C12,'MASTER VOLUME'!$B$3:$U$487,8,0)/4000)*(E12/VLOOKUP(C12,'MASTER VOLUME'!$B$3:$U$487,12,0)) -> 0.943 | J12: =(VLOOKUP(C12,'MASTER VOLUME'!$B$3:$U$487,6,0)*VLOOKUP(C12,'MASTER VOLUME'!$B$3:$U$487,7,0)*VLOOKUP(C12,'MASTER VOLUME'!$B$3:$U$487,8,0)/6000)*(E12/VLOOKUP(C12,'MASTER VOLUME'!$B$3:$U$487,12,0)) -> 0.62866667 | K12: =VLOOKUP(C12,'MASTER VOLUME'!$B$3:$U$487,9,0)*L12 -> 0.05658 | L12: =ROUNDUP(E12/VLOOKUP(C12,'MASTER VOLUME'!$B$3:$U$487,12,0),0) -> 1 | N12: =VLOOKUP(C12,[2]Sheet1!$A$5:$C$87,3,0) -> 37000
B13: 7 | C13: NIC1832-N-E | D13: =VLOOKUP(C13,'MASTER VOLUME'!$B$3:$C$487,2,0) -> I.V CATHETER 18GX1 1/4"/1832 ETFE | E13: 300 | F13: =UPPER(VLOOKUP(C13,'MASTER VOLUME'!$B$3:$AR$549,23,0)) -> PCS | G13: =(VLOOKUP(C13,'MASTER VOLUME'!$B$1:$AD$487,17,0)/VLOOKUP(C13,'MASTER VOLUME'!$B$1:$AD$487,12,0))*E13 -> 1.68 | H13: =(VLOOKUP(C13,'MASTER VOLUME'!$B$3:$S$487,6,0)*VLOOKUP(C13,'MASTER VOLUME'!$B$3:$S$487,7,0)*VLOOKUP(C13,'MASTER VOLUME'!$B$3:$S$487,8,0)/4000)*(E13/VLOOKUP(C13,'MASTER VOLUME'!$B$3:$S$487,12,0)) -> 3.25125 | I13: =(VLOOKUP(C13,'MASTER VOLUME'!$B$3:$U$487,6,0)*VLOOKUP(C13,'MASTER VOLUME'!$B$3:$U$487,7,0)*VLOOKUP(C13,'MASTER VOLUME'!$B$3:$U$487,8,0)/4000)*(E13/VLOOKUP(C13,'MASTER VOLUME'!$B$3:$U$487,12,0)) -> 3.25125 | J13: =(VLOOKUP(C13,'MASTER VOLUME'!$B$3:$U$487,6,0)*VLOOKUP(C13,'MASTER VOLUME'!$B$3:$U$487,7,0)*VLOOKUP(C13,'MASTER VOLUME'!$B$3:$U$487,8,0)/6000)*(E13/VLOOKUP(C13,'MASTER VOLUME'!$B$3:$U$487,12,0)) -> 2.1675 | K13: =VLOOKUP(C13,'MASTER VOLUME'!$B$3:$U$487,9,0)*L13 -> 0.0867 | L13: =ROUNDUP(E13/VLOOKUP(C13,'MASTER VOLUME'!$B$3:$U$487,12,0),0) -> 1 | N13: =VLOOKUP(C13,[2]Sheet1!$A$5:$C$87,3,0) -> 12383
B14: 8 | C14: NIC2032-N-E | D14: =VLOOKUP(C14,'MASTER VOLUME'!$B$3:$C$487,2,0) -> I.V CATHETER 20GX1 1/4"/2032-N-PU | E14: 300 | F14: =UPPER(VLOOKUP(C14,'MASTER VOLUME'!$B$3:$AR$549,23,0)) -> PCS | G14: =(VLOOKUP(C14,'MASTER VOLUME'!$B$1:$AD$487,17,0)/VLOOKUP(C14,'MASTER VOLUME'!$B$1:$AD$487,12,0))*E14 -> 1.68 | H14: =(VLOOKUP(C14,'MASTER VOLUME'!$B$3:$S$487,6,0)*VLOOKUP(C14,'MASTER VOLUME'!$B$3:$S$487,7,0)*VLOOKUP(C14,'MASTER VOLUME'!$B$3:$S$487,8,0)/4000)*(E14/VLOOKUP(C14,'MASTER VOLUME'!$B$3:$S$487,12,0)) -> 3.25125 | I14: =(VLOOKUP(C14,'MASTER VOLUME'!$B$3:$U$487,6,0)*VLOOKUP(C14,'MASTER VOLUME'!$B$3:$U$487,7,0)*VLOOKUP(C14,'MASTER VOLUME'!$B$3:$U$487,8,0)/4000)*(E14/VLOOKUP(C14,'MASTER VOLUME'!$B$3:$U$487,12,0)) -> 3.25125 | J14: =(VLOOKUP(C14,'MASTER VOLUME'!$B$3:$U$487,6,0)*VLOOKUP(C14,'MASTER VOLUME'!$B$3:$U$487,7,0)*VLOOKUP(C14,'MASTER VOLUME'!$B$3:$U$487,8,0)/6000)*(E14/VLOOKUP(C14,'MASTER VOLUME'!$B$3:$U$487,12,0)) -> 2.1675 | K14: =VLOOKUP(C14,'MASTER VOLUME'!$B$3:$U$487,9,0)*L14 -> 0.0867 | L14: =ROUNDUP(E14/VLOOKUP(C14,'MASTER VOLUME'!$B$3:$U$487,12,0),0) -> 1 | N14: =VLOOKUP(C14,[2]Sheet1!$A$5:$C$87,3,0) -> 37710
B15: 9 | C15: NIC2225-N-E | D15: =VLOOKUP(C15,'MASTER VOLUME'!$B$3:$C$487,2,0) -> I.V CATHETER 22GX1"/2225 ETFE | E15: 1500 | F15: =UPPER(VLOOKUP(C15,'MASTER VOLUME'!$B$3:$AR$549,23,0)) -> PCS | G15: =(VLOOKUP(C15,'MASTER VOLUME'!$B$1:$AD$487,17,0)/VLOOKUP(C15,'MASTER VOLUME'!$B$1:$AD$487,12,0))*E15 -> 8.4 | H15: =(VLOOKUP(C15,'MASTER VOLUME'!$B$3:$S$487,6,0)*VLOOKUP(C15,'MASTER VOLUME'!$B$3:$S$487,7,0)*VLOOKUP(C15,'MASTER VOLUME'!$B$3:$S$487,8,0)/4000)*(E15/VLOOKUP(C15,'MASTER VOLUME'!$B$3:$S$487,12,0)) -> 16.25625 | I15: =(VLOOKUP(C15,'MASTER VOLUME'!$B$3:$U$487,6,0)*VLOOKUP(C15,'MASTER VOLUME'!$B$3:$U$487,7,0)*VLOOKUP(C15,'MASTER VOLUME'!$B$3:$U$487,8,0)/4000)*(E15/VLOOKUP(C15,'MASTER VOLUME'!$B$3:$U$487,12,0)) -> 16.25625 | J15: =(VLOOKUP(C15,'MASTER VOLUME'!$B$3:$U$487,6,0)*VLOOKUP(C15,'MASTER VOLUME'!$B$3:$U$487,7,0)*VLOOKUP(C15,'MASTER VOLUME'!$B$3:$U$487,8,0)/6000)*(E15/VLOOKUP(C15,'MASTER VOLUME'!$B$3:$U$487,12,0)) -> 10.8375 | K15: =VLOOKUP(C15,'MASTER VOLUME'!$B$3:$U$487,9,0)*L15 -> 0.0867 | L15: =ROUNDUP(E15/VLOOKUP(C15,'MASTER VOLUME'!$B$3:$U$487,12,0),0) -> 1 | N15: =VLOOKUP(C15,[2]Sheet1!$A$5:$C$87,3,0) -> 63777
B16: 10 | C16: NIC2420-N-E | D16: =VLOOKUP(C16,'MASTER VOLUME'!$B$3:$C$487,2,0) -> I.V CATHETER 24GX3/4"/2420 ETFE | E16: 1000 | F16: =UPPER(VLOOKUP(C16,'MASTER VOLUME'!$B$3:$AR$549,23,0)) -> PCS | G16: =(VLOOKUP(C16,'MASTER VOLUME'!$B$1:$AD$487,17,0)/VLOOKUP(C16,'MASTER VOLUME'!$B$1:$AD$487,12,0))*E16 -> 5.6 | H16: =(VLOOKUP(C16,'MASTER VOLUME'!$B$3:$S$487,6,0)*VLOOKUP(C16,'MASTER VOLUME'!$B$3:$S$487,7,0)*VLOOKUP(C16,'MASTER VOLUME'!$B$3:$S$487,8,0)/4000)*(E16/VLOOKUP(C16,'MASTER VOLUME'!$B$3:$S$487,12,0)) -> 10.8375 | I16: =(VLOOKUP(C16,'MASTER VOLUME'!$B$3:$U$487,6,0)*VLOOKUP(C16,'MASTER VOLUME'!$B$3:$U$487,7,0)*VLOOKUP(C16,'MASTER VOLUME'!$B$3:$U$487,8,0)/4000)*(E16/VLOOKUP(C16,'MASTER VOLUME'!$B$3:$U$487,12,0)) -> 10.8375 | J16: =(VLOOKUP(C16,'MASTER VOLUME'!$B$3:$U$487,6,0)*VLOOKUP(C16,'MASTER VOLUME'!$B$3:$U$487,7,0)*VLOOKUP(C16,'MASTER VOLUME'!$B$3:$U$487,8,0)/6000)*(E16/VLOOKUP(C16,'MASTER VOLUME'!$B$3:$U$487,12,0)) -> 7.225 | K16: =VLOOKUP(C16,'MASTER VOLUME'!$B$3:$U$487,9,0)*L16 -> 0.0867 | L16: =ROUNDUP(E16/VLOOKUP(C16,'MASTER VOLUME'!$B$3:$U$487,12,0),0) -> 1 | N16: =VLOOKUP(C16,[2]Sheet1!$A$5:$C$87,3,0) -> 45508
D18: Nilai DO | E18: 37506900
D19: Biaya Kirim External | E19: 4040 | F19: ** TRANSPORTER : INDAH LOGISTIK, DESTINASI : LUBUK SIKAPING, LEADTIME : 2 - 3 HARI
D20: Total Biaya Kirim | E20: =E19*H5 -> 1033305
D21: Cost Ratio | E21: =E20/E18 -> 0.027549732
C24: LINK :
C25: HARGA INDAH LOGISTIK

Sheet MASTER VOLUME
B1: 1 | C1: 2 | D1: 3 | E1: 4 | F1: 5 | G1: 6 | H1: 7 | I1: 8 | J1: 9 | K1: 10 | L1: 11 | M1: 12 | N1: 13 | O1: 14 | P1: 15 | Q1: 16 | R1: 17 | S1: 18 | T1: 19 | U1: 20 | V1: 21 | W1: 22 | X1: 23 | Y1: 24 | Z1: 25 | AA1: 26 | AB1: 27 | AC1: 28 | AD1: 29
A2: No | B2: NO ITEM | C2: ITEM DESCRIPTION | D2: P (cm) - Inner | E2: L(cm) - Inner | F2: T(cm) - Inner | G2: P (cm) - Outer | H2: L(cm) - Outer | I2: T(cm) - Outer | J2: Kubik - Outer Box | K2: Pcs / 1 Inner Box | L2: Inner Box / 1 Outer Box | M2: Pcs / 1 Outer Box | N2: Outer Box / 1 Layer | O2: Jumlah Tumpukan | P2: Outer Box / 1 Pallet | Q2: Pcs / 1 Pallet | R2: Berat (Kg) | S2: Aktif / Non Aktif | U2: Berat dus luar | W2: QTY | X2: UoM | Y2: BERAT (KG) | Z2: Berat Volumetrik Darat/laut (kg) | AA2: Berat Volumetrik Udara (kg) | AB2: Kubikasi | AC2: Koli | AD2: HD / NHD
A3: 1 | B3: DS01N100 | C3: DISP.SYRINGE 1ML insulin 100 unit | D3: 21 | E3: 14 | F3: 10.7 | G3: 58.5 | H3: 45 | I3: 46.5 | J3: =(G3*H3*I3)/1000000 -> 0.12241125 | K3: 100 | L3: 32 | M3: =K3*L3 -> 3200 | N3: 4 | O3: 4 | P3: =N3*O3 -> 16 | Q3: =M3*P3 -> 51200 | R3: 15.8 | S3: Aktif | X3: pcs | Y3: =R3/M3*W3 -> 0 | Z3: =(G3*H3*I3/4000)*(W3/M3) -> 0 | AA3: =(G3*H3*I3/6000)*(W3/M3) -> 0 | AB3: =(G3*H3*I3/1000000)*(W3/M3) -> 0 | AC3: =ROUNDUP(W3/M3,0) -> 0 | AD3: NHD
A4: 2 | B4: DS01T2613 | C4: DISP.SYRINGE 1ML TB | D4: 21 | E4: 14 | F4: 10.7 | G4: 58.5 | H4: 45 | I4: 46.5 | J4: =(G4*H4*I4)/1000000 -> 0.12241125 | K4: 100 | L4: 32 | M4: =K4*L4 -> 3200 | N4: 4 | O4: 4 | P4: =N4*O4 -> 16 | Q4: =M4*P4 -> 51200 | R4: 15.8 | S4: Aktif | X4: pcs | Y4: =R4/M4*W4 -> 0 | Z4: =(G4*H4*I4/4000)*(W4/M4) -> 0 | AA4: =(G4*H4*I4/6000)*(W4/M4) -> 0 | AB4: =(G4*H4*I4/1000000)*(W4/M4) -> 0 | AC4: =ROUNDUP(W4/M4,0) -> 0 | AD4: NHD
A5: 3 | B5: DS01T2613-N | C5: DISP.SYRINGE 1ML TB 26GX1/2"/2613 LUER SLIP -N | D5: 21 | E5: 14 | F5: 10.7 | G5: 58.5 | H5: 45 | I5: 46.5 | J5: =(G5*H5*I5)/1000000 -> 0.12241125 | K5: 100 | L5: 32 | M5: =K5*L5 -> 3200 | N5: 4 | O5: 4 | P5: =N5*O5 -> 16 | Q5: =M5*P5 -> 51200 | R5: 17.272 | S5: Aktif | X5: pcs | Y5: =R5/M5*W5 -> 0 | Z5: =(G5*H5*I5/4000)*(W5/M5) -> 0 | AA5: =(G5*H5*I5/6000)*(W5/M5) -> 0 | AB5: =(G5*H5*I5/1000000)*(W5/M5) -> 0 | AC5: =ROUNDUP(W5/M5,0) -> 0 | AD5: NHD
A6: 4 | B6: DS01T2613R-N | C6: DISP.SYRINGE 1ML TB 26GX1/2"/2613 LUER SLIP R-N | D6: 21 | E6: 14 | F6: 10.7 | G6: 58.5 | H6: 45 | I6: 46.5 | J6: =(G6*H6*I6)/1000000 -> 0.12241125 | K6: 100 | L6: 32 | M6: =K6*L6 -> 3200 | N6: 4 | O6: 4 | P6: =N6*O6 -> 16 | Q6: =M6*P6 -> 51200 | R6: 17.272 | S6: Aktif | X6: pcs | Y6: =R6/M6*W6 -> 0 | Z6: =(G6*H6*I6/4000)*(W6/M6) -> 0 | AA6: =(G6*H6*I6/6000)*(W6/M6) -> 0 | AB6: =(G6*H6*I6/1000000)*(W6/M6) -> 0 | AC6: =ROUNDUP(W6/M6,0) -> 0 | AD6: NHD
A7: 5 | B7: DS03L2332 | C7: DISP.SYRINGE 3ML (23G X 1 1/4) - E - PACK" | D7: 22 | E7: 21 | F7: 9 | G7: 58.5 | H7: 45.5 | I7: 45.5 | J7: =(G7*H7*I7)/1000000 -> 0.12110962 | K7: 100 | L7: 24 | M7: =K7*L7 -> 2400 | N7: 4 | O7: 4 | P7: =N7*O7 -> 16 | Q7: =M7*P7 -> 38400 | R7: 16.282 | S7: Aktif | X7: pcs | Y7: =R7/M7*W7 -> 0 | Z7: =(G7*H7*I7/4000)*(W7/M7) -> 0 | AA7: =(G7*H7*I7/6000)*(W7/M7) -> 0 | AB7: =(G7*H7*I7/1000000)*(W7/M7) -> 0 | AC7: =ROUNDUP(W7/M7,0) -> 0 | AD7: NHD
A8: 6 | B8: DS03L2332-N | C8: DISP.SYRINGE 3ML LUER LOCK with NEEDLE 23GX1 1/4" | D8: 22 | E8: 21 | F8: 9 | G8: 58.5 | H8: 45.5 | I8: 45.5 | J8: =(G8*H8*I8)/1000000 -> 0.12110962 | K8: 100 | L8: 24 | M8: =K8*L8 -> 2400 | N8: 4 | O8: 4 | P8: =N8*O8 -> 16 | Q8: =M8*P8 -> 38400 | R8: 16.282 | S8: Aktif | X8: pcs | Y8: =R8/M8*W8 -> 0 | Z8: =(G8*H8*I8/4000)*(W8/M8) -> 0 | AA8: =(G8*H8*I8/6000)*(W8/M8) -> 0 | AB8: =(G8*H8*I8/1000000)*(W8/M8) -> 0 | AC8: =ROUNDUP(W8/M8,0) -> 0 | AD8: NHD
A9: 7 | B9: DS03L2332R-N | C9: DISP.SYRINGE 3ML LUER LOCK with NEEDLE 23GX1 1/4" | D9: 22 | E9: 21 | F9: 9 | G9: 58.5 | H9: 45.5 | I9: 45.5 | J9: =(G9*H9*I9)/1000000 -> 0.12110962 | K9: 100 | L9: 24 | M9: =K9*L9 -> 2400 | N9: 4 | O9: 4 | P9: =N9*O9 -> 16 | Q9: =M9*P9 -> 38400 | R9: 16.282 | S9: Aktif | W9: 5000 | X9: pcs | Y9: =R9/M9*W9 -> 33.920833 | Z9: =(G9*H9*I9/4000)*(W9/M9) -> 63.07793 | AA9: =(G9*H9*I9/6000)*(W9/M9) -> 42.051953 | AB9: =(G9*H9*I9/1000000)*(W9/M9) -> 0.25231172 | AC9: =ROUNDUP(W9/M9,0) -> 3 | AD9: NHD
A10: 8 | B10: DS03L2425 | C10: DISP.SYRINGE 3ML(24GX1)" | D10: 22 | E10: 21 | F10: 9 | G10: 58.5 | H10: 45.5 | I10: 45.5 | J10: =(G10*H10*I10)/1000000 -> 0.12110962 | K10: 100 | L10: 24 | M10: =K10*L10 -> 2400 | N10: 4 | O10: 4 | P10: =N10*O10 -> 16 | Q10: =M10*P10 -> 38400 | R10: 16.282 | S10: Aktif | X10: pcs | Y10: =R10/M10*W10 -> 0 | Z10: =(G10*H10*I10/4000)*(W10/M10) -> 0 | AA10: =(G10*H10*I10/6000)*(W10/M10) -> 0 | AB10: =(G10*H10*I10/1000000)*(W10/M10) -> 0 | AC10: =ROUNDUP(W10/M10,0) -> 0 | AD10: NHD
A11: 9 | B11: DS03L2425-N | C11: DISP.SYRINGE 3ML LUER LOCK with NEEDLE 24GX1" | D11: 22 | E11: 21 | F11: 9 | G11: 58.5 | H11: 45.5 | I11: 45.5 | J11: =(G11*H11*I11)/1000000 -> 0.12110962 | K11: 100 | L11: 24 | M11: =K11*L11 -> 2400 | N11: 4 | O11: 4 | P11: =N11*O11 -> 16 | Q11: =M11*P11 -> 38400 | R11: 16.282 | S11: Aktif | X11: pcs | Y11: =R11/M11*W11 -> 0 | Z11: =(G11*H11*I11/4000)*(W11/M11) -> 0 | AA11: =(G11*H11*I11/6000)*(W11/M11) -> 0 | AB11: =(G11*H11*I11/1000000)*(W11/M11) -> 0 | AC11: =ROUNDUP(W11/M11,0) -> 0 | AD11: NHD
A12: 10 | B12: DS03L2425R-N | C12: DISP.SYRINGE 3ML LUER LOCK with NEEDLE 24GX1" | D12: 22 | E12: 21 | F12: 9 | G12: 58.5 | H12: 45.5 | I12: 45.5 | J12: =(G12*H12*I12)/1000000 -> 0.12110962 | K12: 100 | L12: 24 | M12: =K12*L12 -> 2400 | N12: 4 | O12: 4 | P12: =N12*O12 -> 16 | Q12: =M12*P12 -> 38400 | R12: 16.282 | S12: Aktif | X12: pcs | Y12: =R12/M12*W12 -> 0 | Z12: =(G12*H12*I12/4000)*(W12/M12) -> 0 | AA12: =(G12*H12*I12/6000)*(W12/M12) -> 0 | AB12: =(G12*H12*I12/1000000)*(W12/M12) -> 0 | AC12: =ROUNDUP(W12/M12,0) -> 0 | AD12: NHD
A13: 11 | B13: DS03L2432 | C13: DISP.SYRINGE 3ML(24GX1 1/4)" | D13: 22 | E13: 21 | F13: 9 | G13: 58.5 | H13: 45.5 | I13: 45.5 | J13: =(G13*H13*I13)/1000000 -> 0.12110962 | K13: 100 | L13: 24 | M13: =K13*L13 -> 2400 | N13: 4 | O13: 4 | P13: =N13*O13 -> 16 | Q13: =M13*P13 -> 38400 | R13: 16.282 | S13: Aktif | X13: pcs | Y13: =R13/M13*W13 -> 0 | Z13: =(G13*H13*I13/4000)*(W13/M13) -> 0 | AA13: =(G13*H13*I13/6000)*(W13/M13) -> 0 | AB13: =(G13*H13*I13/1000000)*(W13/M13) -> 0 | AC13: =ROUNDUP(W13/M13,0) -> 0 | AD13: NHD
A14: 12 | B14: DS03L2432-N | C14: DISP.SYRINGE 3ML LUER LOCK with NEEDLE 24GX1 1/4" | D14: 22 | E14: 21 | F14: 9 | G14: 58.5 | H14: 45.5 | I14: 45.5 | J14: =(G14*H14*I14)/1000000 -> 0.12110962 | K14: 100 | L14: 24 | M14: =K14*L14 -> 2400 | N14: 4 | O14: 4 | P14: =N14*O14 -> 16 | Q14: =M14*P14 -> 38400 | R14: 15.272 | S14: Aktif | X14: pcs | Y14: =R14/M14*W14 -> 0 | Z14: =(G14*H14*I14/4000)*(W14/M14) -> 0 | AA14: =(G14*H14*I14/6000)*(W14/M14) -> 0 | AB14: =(G14*H14*I14/1000000)*(W14/M14) -> 0 | AC14: =ROUNDUP(W14/M14,0) -> 0 | AD14: NHD
A15: 13 | B15: DS03L-C | C15: DISP.SYRINGE 3ML W.NEEDLE - G - PACK | J15: =(G15*H15*I15)/1000000 -> 0 | M15: =K15*L15 -> 0 | P15: =N15*O15 -> 0 | Q15: =M15*P15 -> 0 | S15: Non Aktif | X15: pcs | Y15: =R15/M15*W15 -> #DIV/0! | Z15: =(G15*H15*I15/4000)*(W15/M15) -> #DIV/0! | AA15: =(G15*H15*I15/6000)*(W15/M15) -> #DIV/0! | AB15: =(G15*H15*I15/1000000)*(W15/M15) -> #DIV/0! | AC15: =ROUNDUP(W15/M15,0) -> #DIV/0! | AD15: NHD
A16: 14 | B16: DS05L2238 | C16: DISP.SYRINGE 5ML W.NEEDLE - E - PACK | D16: 42 | E16: 18.5 | F16: 7.5 | G16: 58 | H16: 45 | I16: 46 | J16: =(G16*H16*I16)/1000000 -> 0.12006 | K16: 100 | L16: 17 | M16: =K16*L16 -> 1700 | N16: 4 | O16: 4 | P16: =N16*O16 -> 16 | Q16: =M16*P16 -> 27200 | R16: 16.5 | S16: Aktif | X16: pcs | Y16: =R16/M16*W16 -> 0 | Z16: =(G16*H16*I16/4000)*(W16/M16) -> 0 | AA16: =(G16*H16*I16/6000)*(W16/M16) -> 0 | AB16: =(G16*H16*I16/1000000)*(W16/M16) -> 0 | AC16: =ROUNDUP(W16/M16,0) -> 0 | AD16: NHD
A17: 15 | B17: DS05L2238-N | C17: DISP.SYRINGE 5ML LUER LOCK with NEEDLE 22Gx1 1/2" | D17: 42 | E17: 18.5 | F17: 7.5 | G17: 58 | H17: 45 | I17: 46 | J17: =(G17*H17*I17)/1000000 -> 0.12006 | K17: 100 | L17: 17 | M17: =K17*L17 -> 1700 | N17: 4 | O17: 4 | P17: =N17*O17 -> 16 | Q17: =M17*P17 -> 27200 | R17: 16.5 | S17: Aktif | X17: pcs | Y17: =R17/M17*W17 -> 0 | Z17: =(G17*H17*I17/4000)*(W17/M17) -> 0 | AA17: =(G17*H17*I17/6000)*(W17/M17) -> 0 | AB17: =(G17*H17*I17/1000000)*(W17/M17) -> 0 | AC17: =ROUNDUP(W17/M17,0) -> 0 | AD17: NHD
A18: 16 | B18: DS05L2238R-N | C18: DISP.SYRINGE 5ML LUER LOCK with NEEDLE 22Gx1 1/2" | D18: 42 | E18: 18.5 | F18: 7.5 | G18: 58 | H18: 45 | I18: 46 | J18: =(G18*H18*I18)/1000000 -> 0.12006 | K18: 100 | L18: 17 | M18: =K18*L18 -> 1700 | N18: 4 | O18: 4 | P18: =N18*O18 -> 16 | Q18: =M18*P18 -> 27200 | R18: 16.5 | S18: Aktif | X18: pcs | Y18: =R18/M18*W18 -> 0 | Z18: =(G18*H18*I18/4000)*(W18/M18) -> 0 | AA18: =(G18*H18*I18/6000)*(W18/M18) -> 0 | AB18: =(G18*H18*I18/1000000)*(W18/M18) -> 0 | AC18: =ROUNDUP(W18/M18,0) -> 0 | AD18: NHD | AE18: =W18/26 -> 0
A19: 17 | B19: DS05L-B | C19: DISP. SYRINGE 5ML W.NEEDLE - G - PACK | D19: 42 | E19: 18.5 | F19: 7.5 | G19: 58 | H19: 45 | I19: 46 | J19: =(G19*H19*I19)/1000000 -> 0.12006 | K19: 100 | L19: 17 | M19: =K19*L19 -> 1700 | N19: 4 | O19: 4 | P19: =N19*O19 -> 16 | Q19: =M19*P19 -> 27200 | R19: 16.5 | S19: Aktif | X19: pcs | Y19: =R19/M19*W19 -> 0 | Z19: =(G19*H19*I19/4000)*(W19/M19) -> 0 | AA19: =(G19*H19*I19/6000)*(W19/M19) -> 0 | AB19: =(G19*H19*I19/1000000)*(W19/M19) -> 0 | AC19: =ROUNDUP(W19/M19,0) -> 0 | AD19: NHD
A20: 18 | B20: DS10L2138 | C20: DISP.SYRINGE 10ML W.NEEDLE - E - PACK | D20: 24 | E20: 20 | F20: 21.5 | G20: 81 | H20: 51 | I20: 24.5 | J20: =(G20*H20*I20)/1000000 -> 0.1012095 | M20: =K20*L20 -> 0 | Q20: =M20*P20 -> 0 | S20: Non Aktif | X20: pcs | Y20: =R20/M20*W20 -> #DIV/0! | Z20: =(G20*H20*I20/4000)*(W20/M20) -> #DIV/0! | AA20: =(G20*H20*I20/6000)*(W20/M20) -> #DIV/0! | AB20: =(G20*H20*I20/1000000)*(W20/M20) -> #DIV/0! | AC20: =ROUNDUP(W20/M20,0) -> #DIV/0! | AD20: NHD
A21: 19 | B21: DS10L2138-N | C21: DISP.SYRINGE 10ML LUER LOCK with NEEDLE 21Gx1 1/2" | D21: 24 | E21: 20 | F21: 21.5 | G21: 81 | H21: 51 | I21: 24.5 | J21: =(G21*H21*I21)/1000000 -> 0.1012095 | K21: 100 | L21: 8 | M21: 1000 | N21: 3 | O21: 5 | P21: =N21*O21 -> 15 | Q21: =M21*P21 -> 15000 | R21: 14.47 | S21: Aktif | X21: pcs | Y21: =R21/M21*W21 -> 0 | Z21: =(G21*H21*I21/4000)*(W21/M21) -> 0 | AA21: =(G21*H21*I21/6000)*(W21/M21) -> 0 | AB21: =(G21*H21*I21/1000000)*(W21/M21) -> 0 | AC21: =ROUNDUP(W21/M21,0) -> 0 | AD21: NHD
A22: 20 | B22: 7023Stc PDM-12-PINK | C22: Thermal Wristband 7023S-12-PDM PINK | D22: 40 | E22: 20 | F22: 5.3 | G22: 60 | H22: 42 | I22: 36.5 | J22: =(G22*H22*I22)/1000000 -> 0.09198 | K22: 500 | L22: 18 | M22: =K22*L22 -> 9000 | N22: 5 | O22: 4 | P22: =N22*O22 -> 20 | Q22: =M22*P22 -> 180000 | R22: 19.1 | S22: Aktif | X22: pcs | Y22: =R22/M22*W22 -> 0 | Z22: =(G22*H22*I22/4000)*(W22/M22) -> 0 | AA22: =(G22*H22*I22/6000)*(W22/M22) -> 0 | AB22: =(G22*H22*I22/1000000)*(W22/M22) -> 0 | AC22: =ROUNDUP(W22/M22,0) -> 0 | AD22: NHD
A23: 21 | B23: DS10L-B | C23: DISP.SYRINGE 10ML W.NEEDLE - G - PACK | D23: 24 | E23: 20 | F23: 21.5 | G23: 81 | H23: 51 | I23: 24.5 | J23: =(G23*H23*I23)/1000000 -> 0.1012095 | K23: 100 | L23: 8 | M23: 1000 | N23: 3 | O23: 5 | P23: =N23*O23 -> 15 | Q23: =M23*P23 -> 15000 | R23: 14.47 | S23: Aktif | X23: pcs | Y23: =R23/M23*W23 -> 0 | Z23: =(G23*H23*I23/4000)*(W23/M23) -> 0 | AA23: =(G23*H23*I23/6000)*(W23/M23) -> 0 | AB23: =(G23*H23*I23/1000000)*(W23/M23) -> 0 | AC23: =ROUNDUP(W23/M23,0) -> 0 | AD23: NHD
A24: 22 | B24: DS20LS | C24: DISP.SYRINGE 20ML W/O NEEDLE | D24: 21 | E24: 21 | F24: 14 | G24: 59.5 | H24: 45.5 | I24: 45 | J24: =(G24*H24*I24)/1000000 -> 0.12182625 | K24: 50 | L24: 16 | M24: =K24*L24 -> 800 | N24: 4 | O24: 4 | P24: =N24*O24 -> 16 | Q24: 15,6 | R24: 15.61 | S24: Aktif | X24: pcs | Y24: =R24/M24*W24 -> 0 | Z24: =(G24*H24*I24/4000)*(W24/M24) -> 0 | AA24: =(G24*H24*I24/6000)*(W24/M24) -> 0 | AB24: =(G24*H24*I24/1000000)*(W24/M24) -> 0 | AC24: =ROUNDUP(W24/M24,0) -> 0 | AD24: NHD
A25: 23 | B25: DS20LS-N | C25: DISP.SYRINGE 20ML without NEEDLE LUER SLIP -N | D25: 21 | E25: 21 | F25: 14 | G25: 59.5 | H25: 45.5 | I25: 45 | J25: =(G25*H25*I25)/1000000 -> 0.12182625 | K25: 50 | L25: 16 | M25: =K25*L25 -> 800 | N25: 4 | O25: 4 | P25: =N25*O25 -> 16 | Q25: 15,6 | R25: 15.61 | S25: Aktif | X25: pcs | Y25: =R25/M25*W25 -> 0 | Z25: =(G25*H25*I25/4000)*(W25/M25) -> 0 | AA25: =(G25*H25*I25/6000)*(W25/M25) -> 0 | AB25: =(G25*H25*I25/1000000)*(W25/M25) -> 0 | AC25: =ROUNDUP(W25/M25,0) -> 0 | AD25: NHD
A26: 24 | B26: DS20LSR-N | C26: DISP.SYRINGE 20ML without NEEDLE LUER SLIP R-N | D26: 21 | E26: 21 | F26: 14 | G26: 59.5 | H26: 45.5 | I26: 45 | J26: =(G26*H26*I26)/1000000 -> 0.12182625 | K26: 50 | L26: 16 | M26: =K26*L26 -> 800 | N26: 4 | O26: 4 | P26: =N26*O26 -> 16 | Q26: =800*4 -> 3200 | R26: 15.61 | S26: Aktif | X26: pcs | Y26: =R26/M26*W26 -> 0 | Z26: =(G26*H26*I26/4000)*(W26/M26) -> 0 | AA26: =(G26*H26*I26/6000)*(W26/M26) -> 0 | AB26: =(G26*H26*I26/1000000)*(W26/M26) -> 0 | AC26: =ROUNDUP(W26/M26,0) -> 0 | AD26: NHD
A27: 25 | B27: DS30LS | C27: DISP.SYR.30ML W/O.NEEDLE(LS) | J27: =(G27*H27*I27)/1000000 -> 0 | M27: =K27*L27 -> 0 | P27: =N27*O27 -> 0 | Q27: =M27*P27 -> 0 | S27: Non Aktif | X27: pcs | Y27: =R27/M27*W27 -> #DIV/0! | Z27: =(G27*H27*I27/4000)*(W27/M27) -> #DIV/0! | AA27: =(G27*H27*I27/6000)*(W27/M27) -> #DIV/0! | AB27: =(G27*H27*I27/1000000)*(W27/M27) -> #DIV/0! | AC27: =ROUNDUP(W27/M27,0) -> #DIV/0! | AD27: NHD
A28: 26 | B28: DS50CT-R-N | C28: DISP.SYRINGE 50ML without NEEDLE Catheter Tip -N | D28: 36 | E28: 21.3 | F28: 15 | G28: 77.5 | H28: 38 | I28: 23.5 | J28: =(G28*H28*I28)/1000000 -> 0.0692075 | K28: 40 | L28: 5 | M28: =K28*L28 -> 200 | N28: 4 | O28: 6 | P28: =N28*O28 -> 24 | Q28: =M28*P28 -> 4800 | R28: 9.095 | S28: Aktif | X28: pcs | Y28: =R28/M28*W28 -> 0 | Z28: =(G28*H28*I28/4000)*(W28/M28) -> 0 | AA28: =(G28*H28*I28/6000)*(W28/M28) -> 0 | AB28: =(G28*H28*I28/1000000)*(W28/M28) -> 0 | AC28: =ROUNDUP(W28/M28,0) -> 0 | AD28: NHD
A29: 27 | B29: DS50CT-N | C29: DISP.SYRINGE 50ML without NEEDLE Catheter Tip -N | D29: 36 | E29: 21.3 | F29: 15 | G29: 77.5 | H29: 38 | I29: 23.5 | J29: =(G29*H29*I29)/1000000 -> 0.0692075 | K29: 40 | L29: 5 | M29: =K29*L29 -> 200 | N29: 4 | O29: 6 | P29: =N29*O29 -> 24 | Q29: =M29*P29 -> 4800 | R29: 9.095 | S29: Aktif | X29: pcs | Y29: =R29/M29*W29 -> 0 | Z29: =(G29*H29*I29/4000)*(W29/M29) -> 0 | AA29: =(G29*H29*I29/6000)*(W29/M29) -> 0 | AB29: =(G29*H29*I29/1000000)*(W29/M29) -> 0 | AC29: =ROUNDUP(W29/M29,0) -> 0 | AD29: NHD
A30: 28 | B30: DS50LS-B | C30: DISP.SYRINGE 50ML-B | M30: =K30*L30 -> 0 | P30: =N30*O30 -> 0 | Q30: =M30*P30 -> 0 | S30: Non Aktif | X30: pcs | Y30: =R30/M30*W30 -> #DIV/0! | Z30: =(G30*H30*I30/4000)*(W30/M30) -> #DIV/0! | AA30: =(G30*H30*I30/6000)*(W30/M30) -> #DIV/0! | AB30: =(G30*H30*I30/1000000)*(W30/M30) -> #DIV/0! | AC30: =ROUNDUP(W30/M30,0) -> #DIV/0! | AD30: NHD
A31: 29 | B31: DS50LS-N | C31: DISP.SYRINGE 50ML without NEEDLE LUER SLIP-N | D31: 28 | E31: 20.5 | F31: 14 | G31: 58 | H31: 45.5 | I31: 46.5 | J31: =(G31*H31*I31)/1000000 -> 0.1227135 | K31: 30 | L31: 12 | M31: =K31*L31 -> 360 | N31: 4 | O31: 4 | P31: =N31*O31 -> 16 | Q31: =M31*P31 -> 5760 | R31: 9.095 | S31: Aktif | X31: pcs | Y31: =R31/M31*W31 -> 0 | Z31: =(G31*H31*I31/4000)*(W31/M31) -> 0 | AA31: =(G31*H31*I31/6000)*(W31/M31) -> 0 | AB31: =(G31*H31*I31/1000000)*(W31/M31) -> 0 | AC31: =ROUNDUP(W31/M31,0) -> 0 | AD31: NHD
A32: 30 | B32: DS50LS-R-N | C32: DISP.SYRINGE.50ML W/O.NEEDLE(LS) BLS E-BEAM | D32: 28 | E32: 20.5 | F32: 14 | G32: 58 | H32: 45.5 | I32: 46.5 | J32: =(G32*H32*I32)/1000000 -> 0.1227135 | K32: 30 | L32: 12 | M32: =K32*L32 -> 360 | N32: 4 | O32: 4 | P32: =N32*O32 -> 16 | Q32: =M32*P32 -> 5760 | R32: 9.095 | S32: Aktif | X32: pcs | Y32: =R32/M32*W32 -> 0 | Z32: =(G32*H32*I32/4000)*(W32/M32) -> 0 | AA32: =(G32*H32*I32/6000)*(W32/M32) -> 0 | AB32: =(G32*H32*I32/1000000)*(W32/M32) -> 0 | AC32: =ROUNDUP(W32/M32,0) -> 0 | AD32: NHD
A33: 31 | B33: DS01T2613-K | C33: DISP.SYRINGE 1ML LUER SLIP W/ NEEDLE 26GX1/2" KAN | D33: 18.5 | E33: 15.5 | F33: 11.5 | G33: 62 | H33: 39 | I33: 49 | J33: =(G33*H33*I33)/1000000 -> 0.118482 | K33: 100 | L33: 32 | M33: =K33*L33 -> 3200 | N33: 5 | O33: 5 | P33: =N33*O33 -> 25 | Q33: =M33*P33 -> 80000 | R33: 14.8 | S33: Aktif | X33: pcs | Y33: =R33/M33*W33 -> 0 | Z33: =(G33*H33*I33/4000)*(W33/M33) -> 0 | AA33: =(G33*H33*I33/6000)*(W33/M33) -> 0 | AB33: =(G33*H33*I33/1000000)*(W33/M33) -> 0 | AC33: =ROUNDUP(W33/M33,0) -> 0 | AD33: NHD
A34: 32 | B34: DS03L2332-K | C34: DISP.SYRINGE 3ML LUER LOCK W/NEEDLE 23GX1-1/4" KAN | D34: 18.5 | E34: 15.5 | F34: 11.5 | G34: 61 | H34: 39 | I34: 49 | J34: =(G34*H34*I34)/1000000 -> 0.116571 | K34: 100 | L34: 30 | M34: =K34*L34 -> 3000 | N34: 5 | O34: 5 | P34: =N34*O34 -> 25 | Q34: =M34*P34 -> 75000 | R34: 17.6 | S34: Aktif | X34: pcs | Y34: =R34/M34*W34 -> 0 | Z34: =(G34*H34*I34/4000)*(W34/M34) -> 0 | AA34: =(G34*H34*I34/6000)*(W34/M34) -> 0 | AB34: =(G34*H34*I34/1000000)*(W34/M34) -> 0 | AC34: =ROUNDUP(W34/M34,0) -> 0 | AD34: NHD
A35: 33 | B35: DS05L2238-K | C35: DISP.SYRINGE 5ml Luer Lock W/Needle 22GX1-1/2" KAN | S35: Non Aktif | X35: pcs | Y35: =R35/M35*W35 -> #DIV/0! | Z35: =(G35*H35*I35/4000)*(W35/M35) -> #DIV/0! | AA35: =(G35*H35*I35/6000)*(W35/M35) -> #DIV/0! | AB35: =(G35*H35*I35/1000000)*(W35/M35) -> #DIV/0! | AC35: =ROUNDUP(W35/M35,0) -> #DIV/0! | AD35: NHD
A36: 34 | B36: SP-60 | C36: SYRINGE PUMP SP-60 | S36: Non Aktif | X36: pcs | Y36: =R36/M36*W36 -> #DIV/0! | Z36: =(G36*H36*I36/4000)*(W36/M36) -> #DIV/0! | AA36: =(G36*H36*I36/6000)*(W36/M36) -> #DIV/0! | AB36: =(G36*H36*I36/1000000)*(W36/M36) -> #DIV/0! | AC36: =ROUNDUP(W36/M36,0) -> #DIV/0! | AD36: NHD
A37: 35 | B37: SP-SMART | C37: SYRINGE PUMP SMARTFUSION SP-SMART | D37: 36 | E37: 21.2 | F37: 23 | G37: 36 | H37: 21 | I37: 23 | J37: =(G37*H37*I37)/1000000 -> 0.017388 | K37: 1 | L37: 1 | M37: =K37*L37 -> 1 | N37: 10 | O37: 10 | P37: =N37*O37 -> 100 | Q37: =M37*P37 -> 100 | R37: 3 | S37: Aktif | X37: pcs | Y37: =R37/M37*W37 -> 0 | Z37: =(G37*H37*I37/4000)*(W37/M37) -> 0 | AA37: =(G37*H37*I37/6000)*(W37/M37) -> 0 | AB37: =(G37*H37*I37/1000000)*(W37/M37) -> 0 | AC37: =ROUNDUP(W37/M37,0) -> 0 | AD37: NHD
A38: 36 | B38: NIC1650 | C38: I.V CATHETER 16GX2"/1650 | D38: 16 | E38: 7.5 | F38: 16.5 | G38: 75 | H38: 34 | I38: 34 | J38: =(G38*H38*I38)/1000000 -> 0.0867 | K38: 50 | L38: 40 | M38: =K38*L38 -> 2000 | N38: 6 | O38: 5 | P38: =N38*O38 -> 30 | Q38: =M38*P38 -> 60000 | R38: 11.2 | S38: Aktif | X38: pcs | Y38: =R38/M38*W38 -> 0 | Z38: =(G38*H38*I38/4000)*(W38/M38) -> 0 | AA38: =(G38*H38*I38/6000)*(W38/M38) -> 0 | AB38: =(G38*H38*I38/1000000)*(W38/M38) -> 0 | AC38: =ROUNDUP(W38/M38,0) -> 0 | AD38: NHD
A39: 37 | B39: NIC1650-N-E | C39: I.V CATHETER 16GX2"/1650-N-PU | D39: 16 | E39: 7.5 | F39: 16 | G39: 75 | H39: 34 | I39: 34 | J39: =(G39*H39*I39)/1000000 -> 0.0867 | K39: 50 | L39: 40 | M39: =K39*L39 -> 2000 | N39: 6 | O39: 5 | P39: =N39*O39 -> 30 | Q39: =M39*P39 -> 60000 | R39: 11.2 | S39: Aktif | X39: pcs | Y39: =R39/M39*W39 -> 0 | Z39: =(G39*H39*I39/4000)*(W39/M39) -> 0 | AA39: =(G39*H39*I39/6000)*(W39/M39) -> 0 | AB39: =(G39*H39*I39/1000000)*(W39/M39) -> 0 | AC39: =ROUNDUP(W39/M39,0) -> 0 | AD39: NHD
A40: 38 | B40: NIC1650-N | C40: I.V CATHETER 16GX2"/1650-N-ETFE | D40: 16 | E40: 7.5 | F40: 16 | G40: 75 | H40: 34 | I40: 34 | J40: =(G40*H40*I40)/1000000 -> 0.0867 | K40: 50 | L40: 40 | M40: =K40*L40 -> 2000 | N40: 6 | O40: 5 | P40: =N40*O40 -> 30 | Q40: =M40*P40 -> 60000 | R40: 11.2 | S40: Aktif | X40: pcs | Y40: =R40/M40*W40 -> 0 | Z40: =(G40*H40*I40/4000)*(W40/M40) -> 0 | AA40: =(G40*H40*I40/6000)*(W40/M40) -> 0 | AB40: =(G40*H40*I40/1000000)*(W40/M40) -> 0 | AC40: =ROUNDUP(W40/M40,0) -> 0 | AD40: NHD
...

Sheet Sheet1
A1: 7 | B1: DS03L2332R-N | C1: DISP.SYRINGE 3ML LUER LOCK with NEEDLE 23GX1 1/4" | D1: 22 | E1: 21 | F1: 9 | G1: 58.5 | H1: 45.5 | I1: 45.5 | J1: =(G1*H1*I1)/1000000 -> 0.12110962 | K1: 100 | L1: 24 | M1: =K1*L1 -> 2400 | N1: 4 | O1: 4 | P1: =N1*O1 -> 16 | Q1: =M1*P1 -> 38400 | R1: 16.282 | S1: Aktif | W1: 9200 | X1: pcs | Y1: =R1/M1*W1 -> 62.414333 | Z1: =(G1*H1*I1/4000)*(W1/M1) -> 116.06339 | AA1: =(G1*H1*I1/6000)*(W1/M1) -> 77.375594 | AB1: =(G1*H1*I1/1000000)*(W1/M1) -> 0.46425356 | AC1: =ROUNDUP(W1/M1,0) -> 4 | AD1: =VLOOKUP(B1,[3]Items!$A$2:$C$6597,3,0) -> NHD
